<?xml version="1.0" encoding="UTF-8"?>
<testsuite name="dataLoader_tests.TestDeviceDataLoader-20220430002352" tests="2" file="dataLoader_tests.py" time="0.005" timestamp="2022-04-30T00:23:57" failures="0" errors="2" skipped="0">
	<testcase classname="dataLoader_tests.TestDeviceDataLoader" name="test_show_data_loader" time="0.003" timestamp="2022-04-30T00:23:57">
		<error type="NameError" message="name 'show_DataLoader' is not defined"><![CDATA[Traceback (most recent call last):
  File "/usr/lib/python3.9/unittest/case.py", line 59, in testPartExecutor
    yield
  File "/usr/lib/python3.9/unittest/case.py", line 593, in run
    self._callTestMethod(testMethod)
  File "/usr/lib/python3.9/unittest/case.py", line 550, in _callTestMethod
    method()
  File "/home/luka/Desktop/Assignment_6/src/unittest/python/dataLoader_tests.py", line 22, in test_show_data_loader
    hit = show_DataLoader()
NameError: name 'show_DataLoader' is not defined
]]></error>
	</testcase>
	<testcase classname="dataLoader_tests.TestDeviceDataLoader" name="test_show_device" time="0.002" timestamp="2022-04-30T00:23:57">
		<error type="NameError" message="name 'show_device' is not defined"><![CDATA[Traceback (most recent call last):
  File "/usr/lib/python3.9/unittest/case.py", line 59, in testPartExecutor
    yield
  File "/usr/lib/python3.9/unittest/case.py", line 593, in run
    self._callTestMethod(testMethod)
  File "/usr/lib/python3.9/unittest/case.py", line 550, in _callTestMethod
    method()
  File "/home/luka/Desktop/Assignment_6/src/unittest/python/dataLoader_tests.py", line 17, in test_show_device
    hit = show_device()
NameError: name 'show_device' is not defined
]]></error>
	</testcase>
</testsuite>
